Workbook
Name _21_06_2024: Loans!$Z$3:$Z$5001
Name Ahmedabad: Loans!$Y$3:$Y$5001
Name Approved: Loans!$AC$3:$AC$5001
Name C200001_: Loans!$C$3:$C$5001
Name Female: Loans!$F$3:$F$5001
Name Gujarat: Loans!$X$3:$X$5001
Name L100001_: Loans!$A$3:$A$5001
Name L100002_: Loans!$C$3:$AE$3
Name L100003_: Loans!$C$4:$AE$4
Name L100004_: Loans!$C$5:$AE$5
Name L100005_: Loans!$C$6:$AE$6
Name L100006_: Loans!$C$7:$AE$7
Name L100007_: Loans!$C$8:$AE$8
Name L100008_: Loans!$C$9:$AE$9
Name L100009_: Loans!$C$10:$AE$10
Name L100010_: Loans!$C$11:$AE$11
Name L100011_: Loans!$C$12:$AE$12
Name L100012_: Loans!$C$13:$AE$13
Name L100013_: Loans!$C$14:$AE$14
Name L100014_: Loans!$C$15:$AE$15
Name L100015_: Loans!$C$16:$AE$16
Name L100016_: Loans!$C$17:$AE$17
Name L100017_: Loans!$C$18:$AE$18
Name L100018_: Loans!$C$19:$AE$19
Name L100019_: Loans!$C$20:$AE$20
Name L100020_: Loans!$C$21:$AE$21
Name L100021_: Loans!$C$22:$AE$22
Name L100022_: Loans!$C$23:$AE$23
Name L100023_: Loans!$C$24:$AE$24
Name L100024_: Loans!$C$25:$AE$25
Name L100025_: Loans!$C$26:$AE$26
Name L100026_: Loans!$C$27:$AE$27
Name L100027_: Loans!$C$28:$AE$28
Name L100028_: Loans!$C$29:$AE$29
Name L100029_: Loans!$C$30:$AE$30
Name L100030_: Loans!$C$31:$AE$31
Name L100031_: Loans!$C$32:$AE$32
Name L100032_: Loans!$C$33:$AE$33
Name L100033_: Loans!$C$34:$AE$34
Name L100034_: Loans!$C$35:$AE$35
Name L100035_: Loans!$C$36:$AE$36
Name L100036_: Loans!$C$37:$AE$37
Name L100037_: Loans!$C$38:$AE$38
Name L100038_: Loans!$C$39:$AE$39
Name L100039_: Loans!$C$40:$AE$40
Name L100040_: Loans!$C$41:$AE$41
Name L100041_: Loans!$C$42:$AE$42
Name L100042_: Loans!$C$43:$AE$43
Name L100043_: Loans!$C$44:$AE$44
Name L100044_: Loans!$C$45:$AE$45
Name L100045_: Loans!$C$46:$AE$46
Name L100046_: Loans!$C$47:$AE$47
Name L100047_: Loans!$C$48:$AE$48
Name L100048_: Loans!$C$49:$AE$49
Name L100049_: Loans!$C$50:$AE$50
Name L100050_: Loans!$C$51:$AE$51
Name L100051_: Loans!$C$52:$AE$52
Name L100052_: Loans!$C$53:$AE$53
Name L100053_: Loans!$C$54:$AE$54
Name L100054_: Loans!$C$55:$AE$55

Sheet KPI
A1: Count of Loan_ID | C1: Row Labels | D1: Count of Loan_Type
A2: 4919 | C2: Business | D2: 973 | J2: Total loan_application
A3: Sum of total_loan_amt | C3: Car | D3: 1021 | J3: =COUNTA(Table2[Loan_ID]) -> 5000
A4: 1.2955312e+10 | C4: Education | D4: 963
A5: Row Labels | B5: Count of Loan_ID | C5: Home | D5: 972 | J5: total loan amt
A6: Approved | B6: 2903 | C6: Personal | D6: 990 | J6: =SUM(Table2[total_loan_amt]) -> 1.3152814e+10
A7: Pending | B7: 997 | C7: Grand Total | D7: 4919
A8: Rejected | B8: 1019 | J8: total approved rate
A9: Grand Total | B9: 4919 | J9: =COUNTIF(Table2[Loan_Status],"approved")/COUNTA(Table2[Loan_ID]) -> 0.5892
J11: total rejected rate
J12: =COUNTA(Table2[Loan_Status],"Rejected")/COUNTA(Table2[Loan_ID]) -> 1.0002
A14: Average of total_loan_amt | J14: average loan amt
A15: 2633728.8 | J15: =AVERAGE(Table2[Loan_Amount]) -> 2449227.9
A17: Row Labels | B17: Average of Credit_Score | J17: Average credit score
A18: Valid | B18: 601.18881 | J18: =AVERAGE(Table2[Credit_Score]) -> 609.045
A19: Grand Total | B19: 601.18881

Sheet Bank Loan Analytics Dashboard
H1: Bank Loan Analytics Dashboard
A3: Total loan_application
A6: total loan amt
A9: total approved rate
A12: total rejected rate
A13: 1038
A15: average loan amt
A18: Average credit score

Sheet pivot tables
D1: Row Labels | E1: Count of Loan_ID | F1: Row Labels | G1: Sum of total_loan_amt | I1: Row Labels | J1: Count of Loan_ID
D2: Invalid | E2: 110 | F2: West | G2: 3.314602e+09 | I2: Approved | J2: 2903
D3: Valid | E3: 4809 | F3: East | G3: 3.2361251e+09 | I3: Pending | J3: 997
D4: Grand Total | E4: 4919 | F4: North | G4: 3.2161794e+09 | I4: Rejected | J4: 1019
F5: South | G5: 3.1884052e+09 | I5: Grand Total | J5: 4919
D6: Sum of Annual_Income | E6: Sum of Loan_Amount | F6: Grand Total | G6: 1.2955312e+10
D7: 6493829528 | E7: 12066518216
A9: Row Labels | B9: Max of Loan_Amount | D9: Row Labels | E9: Count of Loan_ID | G9: Row Labels | H9: Sum of total_loan_amt
A10: Education | B10: 4999426 | D10: No | E10: 2446 | G10: Delhi | H10: 1.9927068e+09
A11: Car | B11: 4997699 | D11: Yes | E11: 2473 | G11: Tamil Nadu | H11: 1.9468881e+09
A12: Home | B12: 4994995 | D12: Grand Total | E12: 4919 | G12: Maharashtra | H12: 1.9452285e+09
A13: Business | B13: 4992857 | G13: Rajasthan | H13: 1.8342915e+09
A14: Personal | B14: 4978015 | D14: Application month | E14: Count of Loan_ID | G14: Gujarat | H14: 1.825782e+09
A15: Grand Total | B15: 4999426 | D15: July | E15: 429 | G15: Karnataka | H15: 1.6958021e+09
D16: October | E16: 427 | G16: UP | H16: 1.686832e+09
D17: December | E17: 427 | G17: Rajasthan | H17: 27780664
D18: August | E18: 427 | G18: Grand Total | H18: 1.2955312e+10
D19: January | E19: 426
D20: September | E20: 413
D21: November | E21: 412
D22: March | E22: 399
D23: June | E23: 397
D24: May | E24: 395
D25: February | E25: 387
D26: April | E26: 380
D27: Grand Total | E27: 4919

Sheet pivot table 2
A1: Row Labels | B1: Sum of total_loan_amt | D1: Row Labels | E1: Count of Credit_Score | G1: Row Labels | H1: Sum of Credit_Score
A2: Business | B2: 1.6859913e+09 | D2: Business | E2: 638 | G2: Excellent | H2: 1533111
A3: Government | B3: 1.6745884e+09 | D3: Government | E3: 634 | G3: Poor | H3: 839
A4: Salaried | B4: 1.7054492e+09 | D4: Salaried | E4: 629 | G4: Grand Total | H4: 1533950
A5: Self-Employed | B5: 1.5931902e+09 | D5: Self-Employed | E5: 604
A6: Grand Total | B6: 6.6592192e+09 | D6: Grand Total | E6: 2505 | G6: Row Labels | H6: Count of Age
G7: 26 | H7: 66
D8: Row Labels | E8: Count of Marital_Status | G8: 58 | H8: 62
D9: Married | E9: 2505 | G9: 49 | H9: 62
D10: Grand Total | E10: 2505 | G10: 50 | H10: 61
G11: 37 | H11: 61
G12: 65 | H12: 58
D13: Row Labels | E13: Count of Education | G13: 40 | H13: 58
A14: Row Labels | B14: Count of Loan_ID | D14: Non-Graduate | E14: 1258 | G14: 43 | H14: 57
A15: Unique | B15: 2505 | D15: Graduate | E15: 1247 | G15: 19 | H15: 57
A16: Grand Total | B16: 2505 | D16: Grand Total | E16: 2505 | G16: 35 | H16: 57
G17: 39 | H17: 57
A18: Row Labels | B18: Count of Customer Name Status | G18: 23 | H18: 56
A19: Submitted | B19: 2505 | G19: 45 | H19: 56
A20: Grand Total | B20: 2505 | G20: 28 | H20: 56
A21: Row Labels | B21: Sum of total_loan_amt | G21: 36 | H21: 56
A22: New Delhi | B22: 1.0783796e+09 | G22: 44 | H22: 55
A23: Mumbai | B23: 1.0398587e+09 | G23: 20 | H23: 54
A24: Chennai | B24: 9.7809031e+08 | G24: 31 | H24: 54
A25: Bengaluru | B25: 9.2628998e+08 | G25: 24 | H25: 54
A26: Ahmedabad | B26: 9.1311091e+08 | G26: 42 | H26: 54
A27: Jaipur | B27: 8.7006336e+08 | G27: 57 | H27: 53
A28: Lucknow | B28: 8.5342642e+08 | G28: 47 | H28: 53
A29: Grand Total | B29: 6.6592192e+09 | G29: 32 | H29: 53
G30: 29 | H30: 52
G31: 61 | H31: 52
G32: 25 | H32: 52
G33: 54 | H33: 52
G34: 41 | H34: 52
G35: 38 | H35: 51
G36: 56 | H36: 51
G37: 18 | H37: 51
G38: 27 | H38: 50
G39: 63 | H39: 50
G40: 22 | H40: 50
...

Sheet KPI2
A2: Count of Loan_ID | B2: Total | D2: Row Labels | E2: Count of Marital_Status
A3: Total | B3: 2505 | D3: Married | E3: 2505
D4: Grand Total | E4: 2505
A5: Row Labels | B5: Count of Valid&invalid credit score
A6: Invalid | B6: 53 | D6: Row Labels | E6: Count of Education
A7: Grand Total | B7: 53 | D7: Graduate | E7: 1247
D8: Non-Graduate | E8: 1258
D9: Grand Total | E9: 2505
A10: Row Labels | B10: Count of Valid&invalid credit score
A11: Valid | B11: 2452
A12: Grand Total | B12: 2452
D13: =$D$14 -> 1
D14: =GETPIVOTDATA("Valid&invalid credit score",$A$10,"Valid&invalid credit score","valid")/GETPIVOTDATA("Valid&invalid credit score",$A$10) -> 1

Sheet Customer Data Quality & Demogra
G2: #VALUE! | H2: Customer Insights & Data Quality Dashboard
B5: Total Record | E5: Invaild credit_score | I5: Data Quality Score | M5: Married customers | Q5: Graduate Percentage
B6: ='KPI2'!$B$3 -> 2505 | E6: ='KPI2'!$B$7 -> 53 | I6: ='KPI2'!$D$14 -> 1 | M6: ='KPI2'!$E$4 -> 2505 | Q6: ='KPI2'!$E$9 -> 2505

Sheet Loans
A1: Loan_ID | B1: Duplicate status | C1: Customer_ID | D1: Customer_Name | E1: Customer Name Status | F1: Gender | G1: Age | H1: Marital_Status | I1: Education | J1: Employment_Type | K1: Annual_Income | L1: income status | M1: Credit_Score | N1: Risk_level | O1: Credit_Score cetogery | P1: Loan Amount Status | Q1: Valid&invalid credit score | R1: Loan_Type | S1: Loan_Amount | T1: Interest_Rate | U1: Loan_Term_Months | V1: EMI | W1: total_loan_amt | X1: State | Y1: City | Z1: Application_Date | AA1: application year | AB1: Application month | AC1: Loan_Status | AD1: Default_Status | AE1: Branch
A2: L100001 | B2: =IF(COUNTIF($A$2:A2,A2)>1,"Duplicate","Unique") -> Unique | C2: C200001 | D2: Vikas Sharma | E2: =IF(C2="","Missing","Submitted") -> Submitted | F2: Female | G2: 29 | H2: Married | I2: Non-Graduate | J2: Salaried | K2: 543962 | L2: =IF(K2="","Missing","Submitted") -> Submitted | M2: 503 | N2: =IF(M2<600,"High_risk",IF(M2>=750,"medium_risk","low_risk")) -> High_risk | O2: =IF(J3<503,"Poor",IF(J3<=550,"Fair",IF(J3<=750,"Good","Excellent"))) -> Excellent | P2: =IF(S2="","Missing","Submitted") -> Submitted | Q2: =IF(AND(M2>=300,M2<=900),"Valid","Invalid") -> Valid | R2: Personal | S2: 541353 | T2: 7.87 | U2: 180 | V2: 3007.52 | W2: =PMT(T2/12,U2,-S2) -> 355037.34 | X2: Gujarat | Y2: Ahmedabad | Z2: 45464 | AA2: =TEXT(Table2[[#This Row],[Application_Date]],"yyy") -> 2024 | AB2: =TEXT(Table2[[#This Row],[Application_Date]],"mmmm") -> June | AC2: Approved | AD2: No | AE2: South
A3: L100002 | B3: =IF(COUNTIF($A$2:A3,A3)>1,"Duplicate","Unique") -> Unique | C3: C200002 | D3: Amit Sharma | E3: =IF(C3="","Missing","Submitted") -> Submitted | F3: Female | G3: 45 | H3: Single | I3: Non-Graduate | J3: Government | K3: 1588760 | L3: =IF(K3="","Missing","Submitted") -> Submitted | M3: 538 | N3: =IF(M3<600,"High_risk",IF(M3>=750,"medium_risk","low_risk")) -> High_risk | O3: =IF(J4<503,"Poor",IF(J4<=550,"Fair",IF(J4<=750,"Good","Excellent"))) -> Excellent | P3: =IF(S3="","Missing","Submitted") -> Submitted | Q3: =IF(AND(M3>=300,M3<=900),"Valid","Invalid") -> Valid | R3: Home | S3: 2682403 | T3: 8.24 | U3: 24 | V3: 111766.79 | W3: =PMT(T3/12,U3,-S3) -> 1841923.3 | X3: Delhi | Y3: New Delhi | Z3: 45465 | AA3: =TEXT(Table2[[#This Row],[Application_Date]],"yyy") -> 2024 | AB3: =TEXT(Table2[[#This Row],[Application_Date]],"mmmm") -> June | AC3: Pending | AD3: Yes | AE3: North
A4: L100003 | B4: =IF(COUNTIF($A$2:A4,A4)>1,"Duplicate","Unique") -> Unique | C4: C200003 | D4: Karan Rao | E4: =IF(C4="","Missing","Submitted") -> Submitted | F4: Male | G4: 41 | H4: Married | I4: Graduate | J4: Self-Employed | K4: 570200 | L4: =IF(K4="","Missing","Submitted") -> Submitted | M4: 705 | N4: =IF(M4<600,"High_risk",IF(M4>=750,"medium_risk","low_risk")) -> low_risk | O4: =IF(J5<503,"Poor",IF(J5<=550,"Fair",IF(J5<=750,"Good","Excellent"))) -> Excellent | P4: =IF(S4="","Missing","Submitted") -> Submitted | Q4: =IF(AND(M4>=300,M4<=900),"Valid","Invalid") -> Valid | R4: Home | S4: 2555459 | T4: 12.79 | U4: 60 | V4: 42590.98 | W4: =PMT(T4/12,U4,-S4) -> 2723693.4 | X4: Karnataka | Y4: Bengaluru | Z4: 45466 | AA4: =TEXT(Table2[[#This Row],[Application_Date]],"yyy") -> 2024 | AB4: =TEXT(Table2[[#This Row],[Application_Date]],"mmmm") -> June | AC4: Rejected | AD4: Yes | AE4: South | AJ4: =COUNTIF(AC2:AC5001,"approved")/COUNTA(A2:A5001) -> 0.5892
A5: L100004 | B5: =IF(COUNTIF($A$2:A5,A5)>1,"Duplicate","Unique") -> Unique | C5: C200004 | D5: Amit Verma | E5: =IF(C5="","Missing","Submitted") -> Submitted | F5: Female | G5: 27 | H5: Married | I5: Graduate | J5: Government | K5: 2479594 | L5: =IF(K5="","Missing","Submitted") -> Submitted | M5: 779 | N5: =IF(M5<600,"High_risk",IF(M5>=750,"medium_risk","low_risk")) -> medium_risk | O5: =IF(J6<503,"Poor",IF(J6<=550,"Fair",IF(J6<=750,"Good","Excellent"))) -> Excellent | P5: =IF(S5="","Missing","Submitted") -> Submitted | Q5: =IF(AND(M5>=300,M5<=900),"Valid","Invalid") -> Valid | R5: Education | S5: 2909690 | T5: 9.14 | U5: 180 | V5: 16164.94 | W5: =PMT(T5/12,U5,-S5) -> 2216213.9 | X5: Karnataka | Y5: Bengaluru | Z5: 45467 | AA5: =TEXT(Table2[[#This Row],[Application_Date]],"yyy") -> 2024 | AB5: =TEXT(Table2[[#This Row],[Application_Date]],"mmmm") -> June | AC5: Approved | AD5: No | AE5: North
A6: L100005 | B6: =IF(COUNTIF($A$2:A6,A6)>1,"Duplicate","Unique") -> Unique | C6: C200005 | D6: Pooja Singh | E6: =IF(C6="","Missing","Submitted") -> Submitted | F6: Female | G6: 39 | H6: Married | I6: Graduate | J6: Government | K6: 878508 | L6: =IF(K6="","Missing","Submitted") -> Submitted | M6: 499 | N6: =IF(M6<600,"High_risk",IF(M6>=750,"medium_risk","low_risk")) -> High_risk | O6: =IF(J7<503,"Poor",IF(J7<=550,"Fair",IF(J7<=750,"Good","Excellent"))) -> Excellent | P6: =IF(S6="","Missing","Submitted") -> Submitted | Q6: =IF(AND(M6>=300,M6<=900),"Valid","Invalid") -> Valid | R6: Education | S6: 2353555 | T6: 11.07 | U6: 24 | V6: 98064.79 | W6: =PMT(T6/12,U6,-S6) -> 2171154.8 | X6: Rajasthan | Y6: Jaipur | Z6: 45468 | AA6: =TEXT(Table2[[#This Row],[Application_Date]],"yyy") -> 2024 | AB6: =TEXT(Table2[[#This Row],[Application_Date]],"mmmm") -> June | AC6: Approved | AD6: Yes | AE6: West
A7: L100006 | B7: =IF(COUNTIF($A$2:A7,A7)>1,"Duplicate","Unique") -> Unique | C7: C200006 | D7: Rohit Patel | E7: =IF(C7="","Missing","Submitted") -> Submitted | F7: Female | G7: 56 | H7: Married | I7: Graduate | J7: Government | K7: 2149153 | L7: =IF(K7="","Missing","Submitted") -> Submitted | M7: 811 | N7: =IF(M7<600,"High_risk",IF(M7>=750,"medium_risk","low_risk")) -> medium_risk | O7: =IF(J8<503,"Poor",IF(J8<=550,"Fair",IF(J8<=750,"Good","Excellent"))) -> Excellent | P7: =IF(S7="","Missing","Submitted") -> Submitted | Q7: =IF(AND(M7>=300,M7<=900),"Valid","Invalid") -> Valid | R7: Home | S7: 3177522 | T7: 13.73 | U7: 12 | V7: 264793.5 | W7: =PMT(T7/12,U7,-S7) -> 3635999.8 | X7: Gujarat | Y7: Ahmedabad | Z7: 45469 | AA7: =TEXT(Table2[[#This Row],[Application_Date]],"yyy") -> 2024 | AB7: =TEXT(Table2[[#This Row],[Application_Date]],"mmmm") -> June | AC7: Approved | AD7: Yes | AE7: East
A8: L100007 | B8: =IF(COUNTIF($A$2:A8,A8)>1,"Duplicate","Unique") -> Unique | C8: C200007 | D8: Anjali Singh | E8: =IF(C8="","Missing","Submitted") -> Submitted | F8: Female | G8: 39 | H8: Single | I8: Graduate | J8: Business | K8: 1851665 | L8: =IF(K8="","Missing","Submitted") -> Submitted | M8: 382 | N8: =IF(M8<600,"High_risk",IF(M8>=750,"medium_risk","low_risk")) -> High_risk | O8: =IF(J9<503,"Poor",IF(J9<=550,"Fair",IF(J9<=750,"Good","Excellent"))) -> Excellent | P8: =IF(S8="","Missing","Submitted") -> Submitted | Q8: =IF(AND(M8>=300,M8<=900),"Valid","Invalid") -> Valid | R8: Education | S8: 4982726 | T8: 10.76 | U8: 60 | V8: 83045.43 | W8: =PMT(T8/12,U8,-S8) -> 4467844.3 | X8: Gujarat | Y8: Ahmedabad | Z8: 45470 | AA8: =TEXT(Table2[[#This Row],[Application_Date]],"yyy") -> 2024 | AB8: =TEXT(Table2[[#This Row],[Application_Date]],"mmmm") -> June | AC8: Pending | AD8: Yes | AE8: North
A9: L100008 | B9: =IF(COUNTIF($A$2:A9,A9)>1,"Duplicate","Unique") -> Unique | C9: C200008 | D9: Vikas Sharma | E9: =IF(C9="","Missing","Submitted") -> Submitted | F9: Female | G9: 27 | H9: Single | I9: Graduate | J9: Business | K9: 0 | L9: =IF(K9="","Missing","Submitted") -> Submitted | M9: 493 | N9: =IF(M9<600,"High_risk",IF(M9>=750,"medium_risk","low_risk")) -> High_risk | O9: =IF(J10<503,"Poor",IF(J10<=550,"Fair",IF(J10<=750,"Good","Excellent"))) -> Excellent | P9: =IF(S9="","Missing","Submitted") -> Submitted | Q9: =IF(AND(M9>=300,M9<=900),"Valid","Invalid") -> Valid | R9: Education | S9: 595443 | T9: 18.99 | U9: 36 | V9: 16540.08 | W9: =PMT(T9/12,U9,-S9) -> 942288.55 | X9: Karnataka | Y9: Bengaluru | Z9: 45471 | AA9: =TEXT(Table2[[#This Row],[Application_Date]],"yyy") -> 2024 | AB9: =TEXT(Table2[[#This Row],[Application_Date]],"mmmm") -> June | AC9: Rejected | AD9: Yes | AE9: West
A10: L100009 | B10: =IF(COUNTIF($A$2:A10,A10)>1,"Duplicate","Unique") -> Unique | C10: C200009 | D10: Priya Mehta | E10: =IF(C10="","Missing","Submitted") -> Submitted | F10: Female | G10: 54 | H10: Single | I10: Non-Graduate | J10: Self-Employed | K10: 1294948 | L10: =IF(K10="","Missing","Submitted") -> Submitted | M10: 386 | N10: =IF(M10<600,"High_risk",IF(M10>=750,"medium_risk","low_risk")) -> High_risk | O10: =IF(J11<503,"Poor",IF(J11<=550,"Fair",IF(J11<=750,"Good","Excellent"))) -> Excellent | P10: =IF(S10="","Missing","Submitted") -> Submitted | Q10: =IF(AND(M10>=300,M10<=900),"Valid","Invalid") -> Valid | R10: Education | S10: 415846 | T10: 15.08 | U10: 60 | V10: 6930.77 | W10: =PMT(T10/12,U10,-S10) -> 522579.81 | X10: Gujarat | Y10: Ahmedabad | Z10: 45472 | AA10: =TEXT(Table2[[#This Row],[Application_Date]],"yyy") -> 2024 | AB10: =TEXT(Table2[[#This Row],[Application_Date]],"mmmm") -> June | AC10: Rejected | AD10: No | AE10: West
A11: L100010 | B11: =IF(COUNTIF($A$2:A11,A11)>1,"Duplicate","Unique") -> Unique | C11: C200010 | D11: Priya Verma | E11: =IF(C11="","Missing","Submitted") -> Submitted | F11: Male | G11: 27 | H11: Single | I11: Non-Graduate | J11: Government | K11: 696488 | L11: =IF(K11="","Missing","Submitted") -> Submitted | M11: 650 | N11: =IF(M11<600,"High_risk",IF(M11>=750,"medium_risk","low_risk")) -> low_risk | O11: =IF(J12<503,"Poor",IF(J12<=550,"Fair",IF(J12<=750,"Good","Excellent"))) -> Excellent | P11: =IF(S11="","Missing","Submitted") -> Submitted | Q11: =IF(AND(M11>=300,M11<=900),"Valid","Invalid") -> Valid | R11: Education | S11: 4215189 | T11: 9.02 | U11: 36 | V11: 117088.58 | W11: =PMT(T11/12,U11,-S11) -> 3168417.1 | X11: Karnataka | Y11: Bengaluru | Z11: 45473 | AA11: =TEXT(Table2[[#This Row],[Application_Date]],"yyy") -> 2024 | AB11: =TEXT(Table2[[#This Row],[Application_Date]],"mmmm") -> June | AC11: Pending | AD11: Yes | AE11: South
A12: L100011 | B12: =IF(COUNTIF($A$2:A12,A12)>1,"Duplicate","Unique") -> Unique | C12: C200011 | D12: Priya Sharma | E12: =IF(C12="","Missing","Submitted") -> Submitted | F12: Male | G12: 38 | H12: Single | I12: Non-Graduate | J12: Business | K12: 1736558 | L12: =IF(K12="","Missing","Submitted") -> Submitted | M12: 359 | N12: =IF(M12<600,"High_risk",IF(M12>=750,"medium_risk","low_risk")) -> High_risk | O12: =IF(J13<503,"Poor",IF(J13<=550,"Fair",IF(J13<=750,"Good","Excellent"))) -> Excellent | P12: =IF(S12="","Missing","Submitted") -> Submitted | Q12: =IF(AND(M12>=300,M12<=900),"Valid","Invalid") -> Valid | R12: Car | S12: 2579162 | T12: 15.09 | U12: 36 | V12: 71643.39 | W12: =PMT(T12/12,U12,-S12) -> 3243296.2 | X12: Karnataka | Y12: Bengaluru | Z12: 45474 | AA12: =TEXT(Table2[[#This Row],[Application_Date]],"yyy") -> 2024 | AB12: =TEXT(Table2[[#This Row],[Application_Date]],"mmmm") -> July | AC12: Rejected | AD12: No | AE12: East
A13: L100012 | B13: =IF(COUNTIF($A$2:A13,A13)>1,"Duplicate","Unique") -> Unique | C13: C200012 | D13: 0 | E13: =IF(C13="","Missing","Submitted") -> Submitted | F13: Male | G13: 33 | H13: Single | I13: Graduate | J13: Self-Employed | K13: 1242862 | L13: =IF(K13="","Missing","Submitted") -> Submitted | M13: 306 | N13: =IF(M13<600,"High_risk",IF(M13>=750,"medium_risk","low_risk")) -> High_risk | O13: =IF(J14<503,"Poor",IF(J14<=550,"Fair",IF(J14<=750,"Good","Excellent"))) -> Excellent | P13: =IF(S13="","Missing","Submitted") -> Submitted | Q13: =IF(AND(M13>=300,M13<=900),"Valid","Invalid") -> Valid | R13: Business | S13: 2324907 | T13: 16.73 | U13: 36 | V13: 64580.75 | W13: =PMT(T13/12,U13,-S13) -> 3241307.8 | X13: Tamil Nadu | Y13: Chennai | Z13: 45475 | AA13: =TEXT(Table2[[#This Row],[Application_Date]],"yyy") -> 2024 | AB13: =TEXT(Table2[[#This Row],[Application_Date]],"mmmm") -> July | AC13: Approved | AD13: No | AE13: West
A14: L100013 | B14: =IF(COUNTIF($A$2:A14,A14)>1,"Duplicate","Unique") -> Unique | C14: C200013 | D14: Amit Gupta | E14: =IF(C14="","Missing","Submitted") -> Submitted | F14: Male | G14: 19 | H14: Married | I14: Non-Graduate | J14: Salaried | K14: 397582 | L14: =IF(K14="","Missing","Submitted") -> Submitted | M14: 472 | N14: =IF(M14<600,"High_risk",IF(M14>=750,"medium_risk","low_risk")) -> High_risk | O14: =IF(J15<503,"Poor",IF(J15<=550,"Fair",IF(J15<=750,"Good","Excellent"))) -> Excellent | P14: =IF(S14="","Missing","Submitted") -> Submitted | Q14: =IF(AND(M14>=300,M14<=900),"Valid","Invalid") -> Valid | R14: Personal | S14: 3727101 | T14: 7.83 | U14: 60 | V14: 62118.35 | W14: =PMT(T14/12,U14,-S14) -> 2431933.4 | X14: Karnataka | Y14: Bengaluru | Z14: 45476 | AA14: =TEXT(Table2[[#This Row],[Application_Date]],"yyy") -> 2024 | AB14: =TEXT(Table2[[#This Row],[Application_Date]],"mmmm") -> July | AC14: Rejected | AD14: No | AE14: North
A15: L100014 | B15: =IF(COUNTIF($A$2:A15,A15)>1,"Duplicate","Unique") -> Unique | C15: C200014 | D15: Priya Verma | E15: =IF(C15="","Missing","Submitted") -> Submitted | F15: Female | G15: 48 | H15: Single | I15: Graduate | J15: Business | K15: 805721 | L15: =IF(K15="","Missing","Submitted") -> Submitted | M15: 681 | N15: =IF(M15<600,"High_risk",IF(M15>=750,"medium_risk","low_risk")) -> low_risk | O15: =IF(J16<503,"Poor",IF(J16<=550,"Fair",IF(J16<=750,"Good","Excellent"))) -> Excellent | P15: =IF(S15="","Missing","Submitted") -> Submitted | Q15: =IF(AND(M15>=300,M15<=900),"Valid","Invalid") -> Valid | R15: Home | S15: 2156689 | T15: 10.67 | U15: 120 | V15: 17972.41 | W15: =PMT(T15/12,U15,-S15) -> 1917656 | X15: Karnataka | Y15: Bengaluru | Z15: 45477 | AA15: =TEXT(Table2[[#This Row],[Application_Date]],"yyy") -> 2024 | AB15: =TEXT(Table2[[#This Row],[Application_Date]],"mmmm") -> July | AC15: Approved | AD15: No | AE15: East
A16: L100015 | B16: =IF(COUNTIF($A$2:A16,A16)>1,"Duplicate","Unique") -> Unique | C16: C200015 | D16: Karan Mehta | E16: =IF(C16="","Missing","Submitted") -> Submitted | F16: Female | G16: 43 | H16: Married | I16: Non-Graduate | J16: Government | K16: 1901274 | L16: =IF(K16="","Missing","Submitted") -> Submitted | M16: 543 | N16: =IF(M16<600,"High_risk",IF(M16>=750,"medium_risk","low_risk")) -> High_risk | O16: =IF(J17<503,"Poor",IF(J17<=550,"Fair",IF(J17<=750,"Good","Excellent"))) -> Excellent | P16: =IF(S16="","Missing","Submitted") -> Submitted | Q16: =IF(AND(M16>=300,M16<=900),"Valid","Invalid") -> Valid | R16: Business | S16: 3081251 | T16: 7.24 | U16: 24 | V16: 128385.46 | W16: =PMT(T16/12,U16,-S16) -> 1859043.8 | X16: UP | Y16: Lucknow | Z16: 45478 | AA16: =TEXT(Table2[[#This Row],[Application_Date]],"yyy") -> 2024 | AB16: =TEXT(Table2[[#This Row],[Application_Date]],"mmmm") -> July | AC16: Pending | AD16: No | AE16: West
A17: L100016 | B17: =IF(COUNTIF($A$2:A17,A17)>1,"Duplicate","Unique") -> Unique | C17: C200016 | D17: Rohit Verma | E17: =IF(C17="","Missing","Submitted") -> Submitted | F17: Male | G17: 62 | H17: Married | I17: Graduate | J17: Government | K17: 1697572 | L17: =IF(K17="","Missing","Submitted") -> Submitted | M17: 559 | N17: =IF(M17<600,"High_risk",IF(M17>=750,"medium_risk","low_risk")) -> High_risk | O17: =IF(J18<503,"Poor",IF(J18<=550,"Fair",IF(J18<=750,"Good","Excellent"))) -> Excellent | P17: =IF(S17="","Missing","Submitted") -> Submitted | Q17: =IF(AND(M17>=300,M17<=900),"Valid","Invalid") -> Valid | R17: Business | S17: 141450 | T17: 17.38 | U17: 120 | V17: 1178.75 | W17: =PMT(T17/12,U17,-S17) -> 204866.75 | X17: Rajasthan | Y17: Jaipur | Z17: 45479 | AA17: =TEXT(Table2[[#This Row],[Application_Date]],"yyy") -> 2024 | AB17: =TEXT(Table2[[#This Row],[Application_Date]],"mmmm") -> July | AC17: Rejected | AD17: Yes | AE17: South
A18: L100017 | B18: =IF(COUNTIF($A$2:A18,A18)>1,"Duplicate","Unique") -> Unique | C18: C200017 | D18: Karan Gupta | E18: =IF(C18="","Missing","Submitted") -> Submitted | F18: Female | G18: 60 | H18: Married | I18: Graduate | J18: Business | K18: 1213000 | L18: =IF(K18="","Missing","Submitted") -> Submitted | M18: 873 | N18: =IF(M18<600,"High_risk",IF(M18>=750,"medium_risk","low_risk")) -> medium_risk | O18: =IF(J19<503,"Poor",IF(J19<=550,"Fair",IF(J19<=750,"Good","Excellent"))) -> Excellent | P18: =IF(S18="","Missing","Submitted") -> Submitted | Q18: =IF(AND(M18>=300,M18<=900),"Valid","Invalid") -> Valid | R18: Education | S18: 1208080 | T18: 18.64 | U18: 180 | V18: 6711.56 | W18: =PMT(T18/12,U18,-S18) -> 1876550.9 | X18: Delhi | Y18: New Delhi | Z18: 45480 | AA18: =TEXT(Table2[[#This Row],[Application_Date]],"yyy") -> 2024 | AB18: =TEXT(Table2[[#This Row],[Application_Date]],"mmmm") -> July | AC18: Pending | AD18: Yes | AE18: South
A19: L100018 | B19: =IF(COUNTIF($A$2:A19,A19)>1,"Duplicate","Unique") -> Unique | C19: C200018 | D19: Vikas Sharma | E19: =IF(C19="","Missing","Submitted") -> Submitted | F19: Female | G19: 40 | H19: Married | I19: Non-Graduate | J19: Self-Employed | K19: 1551295 | L19: =IF(K19="","Missing","Submitted") -> Submitted | M19: 539 | N19: =IF(M19<600,"High_risk",IF(M19>=750,"medium_risk","low_risk")) -> High_risk | O19: =IF(J20<503,"Poor",IF(J20<=550,"Fair",IF(J20<=750,"Good","Excellent"))) -> Excellent | P19: =IF(S19="","Missing","Submitted") -> Submitted | Q19: =IF(AND(M19>=300,M19<=900),"Valid","Invalid") -> Valid | R19: Personal | S19: 2922324 | T19: 11.19 | U19: 36 | V19: 81175.67 | W19: =PMT(T19/12,U19,-S19) -> 2725067.1 | X19: Maharashtra | Y19: Mumbai | Z19: 45481 | AA19: =TEXT(Table2[[#This Row],[Application_Date]],"yyy") -> 2024 | AB19: =TEXT(Table2[[#This Row],[Application_Date]],"mmmm") -> July | AC19: Approved | AD19: No | AE19: South
A20: L100019 | B20: =IF(COUNTIF($A$2:A20,A20)>1,"Duplicate","Unique") -> Unique | C20: C200019 | D20: Vikas Mehta | E20: =IF(C20="","Missing","Submitted") -> Submitted | F20: Male | G20: 23 | H20: Single | I20: Non-Graduate | J20: Government | K20: 367239 | L20: =IF(K20="","Missing","Submitted") -> Submitted | M20: 317 | N20: =IF(M20<600,"High_risk",IF(M20>=750,"medium_risk","low_risk")) -> High_risk | O20: =IF(J21<503,"Poor",IF(J21<=550,"Fair",IF(J21<=750,"Good","Excellent"))) -> Excellent | P20: =IF(S20="","Missing","Submitted") -> Submitted | Q20: =IF(AND(M20>=300,M20<=900),"Valid","Invalid") -> Valid | R20: Business | S20: 1780928 | T20: 12.2 | U20: 60 | V20: 29682.13 | W20: =PMT(T20/12,U20,-S20) -> 1810610.1 | X20: Maharashtra | Y20: Mumbai | Z20: 45482 | AA20: =TEXT(Table2[[#This Row],[Application_Date]],"yyy") -> 2024 | AB20: =TEXT(Table2[[#This Row],[Application_Date]],"mmmm") -> July | AC20: Pending | AD20: No | AE20: East
A21: L100020 | B21: =IF(COUNTIF($A$2:A21,A21)>1,"Duplicate","Unique") -> Unique | C21: C200020 | D21: Neha Patel | E21: =IF(C21="","Missing","Submitted") -> Submitted | F21: Male | G21: 30 | H21: Married | I21: Non-Graduate | J21: Business | K21: 346667 | L21: =IF(K21="","Missing","Submitted") -> Submitted | M21: 588 | N21: =IF(M21<600,"High_risk",IF(M21>=750,"medium_risk","low_risk")) -> High_risk | O21: =IF(J22<503,"Poor",IF(J22<=550,"Fair",IF(J22<=750,"Good","Excellent"))) -> Excellent | P21: =IF(S21="","Missing","Submitted") -> Submitted | Q21: =IF(AND(M21>=300,M21<=900),"Valid","Invalid") -> Valid | R21: Home | S21: 3794465 | T21: 12.72 | U21: 12 | V21: 316205.42 | W21: =PMT(T21/12,U21,-S21) -> 4022821.7 | X21: UP | Y21: Lucknow | Z21: 45483 | AA21: =TEXT(Table2[[#This Row],[Application_Date]],"yyy") -> 2024 | AB21: =TEXT(Table2[[#This Row],[Application_Date]],"mmmm") -> July | AC21: Pending | AD21: No | AE21: North
A22: L100021 | B22: =IF(COUNTIF($A$2:A22,A22)>1,"Duplicate","Unique") -> Unique | C22: C200021 | D22: Rahul Das | E22: =IF(C22="","Missing","Submitted") -> Submitted | F22: Female | G22: 27 | H22: Married | I22: Graduate | J22: Business | K22: 1126432 | L22: =IF(K22="","Missing","Submitted") -> Submitted | M22: 538 | N22: =IF(M22<600,"High_risk",IF(M22>=750,"medium_risk","low_risk")) -> High_risk | O22: =IF(J23<503,"Poor",IF(J23<=550,"Fair",IF(J23<=750,"Good","Excellent"))) -> Excellent | P22: =IF(S22="","Missing","Submitted") -> Submitted | Q22: =IF(AND(M22>=300,M22<=900),"Valid","Invalid") -> Valid | R22: Education | S22: 729043 | T22: 18.8 | U22: 36 | V22: 20251.19 | W22: =PMT(T22/12,U22,-S22) -> 1142167.4 | X22: Maharashtra | Y22: Mumbai | Z22: 45484 | AA22: =TEXT(Table2[[#This Row],[Application_Date]],"yyy") -> 2024 | AB22: =TEXT(Table2[[#This Row],[Application_Date]],"mmmm") -> July | AC22: Approved | AD22: Yes | AE22: West
A23: L100022 | B23: =IF(COUNTIF($A$2:A23,A23)>1,"Duplicate","Unique") -> Unique | C23: C200022 | D23: Pooja Rao | E23: =IF(C23="","Missing","Submitted") -> Submitted | F23: Female | G23: 49 | H23: Single | I23: Graduate | J23: Government | K23: 279137 | L23: =IF(K23="","Missing","Submitted") -> Submitted | M23: 552 | N23: =IF(M23<600,"High_risk",IF(M23>=750,"medium_risk","low_risk")) -> High_risk | O23: =IF(J24<503,"Poor",IF(J24<=550,"Fair",IF(J24<=750,"Good","Excellent"))) -> Excellent | P23: =IF(S23="","Missing","Submitted") -> Submitted | Q23: =IF(AND(M23>=300,M23<=900),"Valid","Invalid") -> Valid | R23: Car | S23: 1018554 | T23: 8.77 | U23: 180 | V23: 5658.63 | W23: =PMT(T23/12,U23,-S23) -> 744393.21 | X23: Gujarat | Y23: Ahmedabad | Z23: 45485 | AA23: =TEXT(Table2[[#This Row],[Application_Date]],"yyy") -> 2024 | AB23: =TEXT(Table2[[#This Row],[Application_Date]],"mmmm") -> July | AC23: Pending | AD23: Yes | AE23: West
A24: L100023 | B24: =IF(COUNTIF($A$2:A24,A24)>1,"Duplicate","Unique") -> Unique | C24: C200023 | D24: Rohit Singh | E24: =IF(C24="","Missing","Submitted") -> Submitted | F24: Male | G24: 27 | H24: Single | I24: Graduate | J24: Self-Employed | K24: 869257 | L24: =IF(K24="","Missing","Submitted") -> Submitted | M24: 669 | N24: =IF(M24<600,"High_risk",IF(M24>=750,"medium_risk","low_risk")) -> low_risk | O24: =IF(J25<503,"Poor",IF(J25<=550,"Fair",IF(J25<=750,"Good","Excellent"))) -> Excellent | P24: =IF(S24="","Missing","Submitted") -> Submitted | Q24: =IF(AND(M24>=300,M24<=900),"Valid","Invalid") -> Valid | R24: Business | S24: 761014 | T24: 9.39 | U24: 24 | V24: 31708.92 | W24: =PMT(T24/12,U24,-S24) -> 595494.02 | X24: Tamil Nadu | Y24: Chennai | Z24: 45486 | AA24: =TEXT(Table2[[#This Row],[Application_Date]],"yyy") -> 2024 | AB24: =TEXT(Table2[[#This Row],[Application_Date]],"mmmm") -> July | AC24: Rejected | AD24: Yes | AE24: East
A25: L100024 | B25: =IF(COUNTIF($A$2:A25,A25)>1,"Duplicate","Unique") -> Unique | C25: C200024 | D25: Amit Rao | E25: =IF(C25="","Missing","Submitted") -> Submitted | F25: Female | G25: 29 | H25: Married | I25: Graduate | J25: Business | K25: 2462493 | L25: =IF(K25="","Missing","Submitted") -> Submitted | M25: 389 | N25: =IF(M25<600,"High_risk",IF(M25>=750,"medium_risk","low_risk")) -> High_risk | O25: =IF(J26<503,"Poor",IF(J26<=550,"Fair",IF(J26<=750,"Good","Excellent"))) -> Excellent | P25: =IF(S25="","Missing","Submitted") -> Submitted | Q25: =IF(AND(M25>=300,M25<=900),"Valid","Invalid") -> Valid | R25: Personal | S25: 4207835 | T25: 15.6 | U25: 120 | V25: 35065.29 | W25: =PMT(T25/12,U25,-S25) -> 5470185.5 | X25: UP | Y25: Lucknow | Z25: 45487 | AA25: =TEXT(Table2[[#This Row],[Application_Date]],"yyy") -> 2024 | AB25: =TEXT(Table2[[#This Row],[Application_Date]],"mmmm") -> July | AC25: Pending | AD25: No | AE25: South
... A80: L100079 | B80: =IF(COUNTIF($A$2:A80,A80)>1,"Duplicate","Unique") -> Unique | C80: C200079 | D80: Karan Gupta | E80: =IF(C80="","Missing","Submitted") -> Submitted | F80: Female | G80: 27 | H80: Married | I80: Graduate | J80: Salaried | K80: 607040 | L80: =IF(K80="","Missing","Submitted") -> Submitted | M80: 893 | N80: =IF(M80<600,"High_risk",IF(M80>=750,"medium_risk","low_risk")) -> medium_risk | O80: =IF(J81<503,"Poor",IF(J81<=550,"Fair",IF(J81<=750,"Good","Excellent"))) -> Excellent | P80: =IF(S80="","Missing","Submitted") -> Submitted | Q80: =IF(AND(M80>=300,M80<=900),"Valid","Invalid") -> Valid | R80: Education | S80: 598985 | T80: 7.33 | U80: 24 | V80: 24957.71 | W80: =PMT(T80/12,U80,-S80) -> 365883.93 | X80: Karnataka | Y80: Bengaluru | Z80: 45542 | AA80: =TEXT(Table2[[#This Row],[Application_Date]],"yyy") -> 2024 | AB80: =TEXT(Table2[[#This Row],[Application_Date]],"mmmm") -> September | AC80: Pending | AD80: Yes | AE80: North
A81: L100080 | B81: =IF(COUNTIF($A$2:A81,A81)>1,"Duplicate","Unique") -> Unique | C81: C200080 | D81: Sneha Verma | E81: =IF(C81="","Missing","Submitted") -> Submitted | F81: Male | G81: 50 | H81: Single | I81: Non-Graduate | J81: Self-Employed | K81: 1206795 | L81: =IF(K81="","Missing","Submitted") -> Submitted | M81: 400 | N81: =IF(M81<600,"High_risk",IF(M81>=750,"medium_risk","low_risk")) -> High_risk | O81: =IF(J82<503,"Poor",IF(J82<=550,"Fair",IF(J82<=750,"Good","Excellent"))) -> Excellent | P81: =IF(S81="","Missing","Submitted") -> Submitted | Q81: =IF(AND(M81>=300,M81<=900),"Valid","Invalid") -> Valid | R81: Education | S81: 0 | T81: 14.8 | U81: 120 | V81: 2083.33 | W81: 0 | X81: Rajasthan | Y81: Jaipur | Z81: 45543 | AA81: =TEXT(Table2[[#This Row],[Application_Date]],"yyy") -> 2024 | AB81: =TEXT(Table2[[#This Row],[Application_Date]],"mmmm") -> September | AC81: Rejected | AD81: Yes | AE81: North
A82: L100081 | B82: =IF(COUNTIF($A$2:A82,A82)>1,"Duplicate","Unique") -> Unique | C82: C200081 | D82: 0 | E82: =IF(C82="","Missing","Submitted") -> Submitted | F82: Male | G82: 41 | H82: Married | I82: Non-Graduate | J82: Salaried | K82: 2292556 | L82: =IF(K82="","Missing","Submitted") -> Submitted | M82: 788 | N82: =IF(M82<600,"High_risk",IF(M82>=750,"medium_risk","low_risk")) -> medium_risk | O82: =IF(J83<503,"Poor",IF(J83<=550,"Fair",IF(J83<=750,"Good","Excellent"))) -> Excellent | P82: =IF(S82="","Missing","Submitted") -> Submitted | Q82: =IF(AND(M82>=300,M82<=900),"Valid","Invalid") -> Valid | R82: Home | S82: 1620729 | T82: 7.79 | U82: 60 | V82: 27012.15 | W82: =PMT(T82/12,U82,-S82) -> 1052123.2 | X82: Delhi | Y82: New Delhi | Z82: 45544 | AA82: =TEXT(Table2[[#This Row],[Application_Date]],"yyy") -> 2024 | AB82: =TEXT(Table2[[#This Row],[Application_Date]],"mmmm") -> September | AC82: Pending | AD82: No | AE82: South
A83: L100082 | B83: =IF(COUNTIF($A$2:A83,A83)>1,"Duplicate","Unique") -> Unique | C83: C200082 | D83: Amit Gupta | E83: =IF(C83="","Missing","Submitted") -> Submitted | F83: Male | G83: 21 | H83: Single | I83: Non-Graduate | J83: Government | K83: 1588219 | L83: =IF(K83="","Missing","Submitted") -> Submitted | M83: 330 | N83: =IF(M83<600,"High_risk",IF(M83>=750,"medium_risk","low_risk")) -> High_risk | O83: =IF(J84<503,"Poor",IF(J84<=550,"Fair",IF(J84<=750,"Good","Excellent"))) -> Excellent | P83: =IF(S83="","Missing","Submitted") -> Submitted | Q83: =IF(AND(M83>=300,M83<=900),"Valid","Invalid") -> Valid | R83: Business | S83: 2701587 | T83: 8.77 | U83: 36 | V83: 75044.08 | W83: =PMT(T83/12,U83,-S83) -> 1974409.8 | X83: Gujarat | Y83: Ahmedabad | Z83: 45545 | AA83: =TEXT(Table2[[#This Row],[Application_Date]],"yyy") -> 2024 | AB83: =TEXT(Table2[[#This Row],[Application_Date]],"mmmm") -> September | AC83: Approved | AD83: No | AE83: South
A84: L100083 | B84: =IF(COUNTIF($A$2:A84,A84)>1,"Duplicate","Unique") -> Unique | C84: C200083 | D84: Rohit Verma | E84: =IF(C84="","Missing","Submitted") -> Submitted | F84: Female | G84: 47 | H84: Single | I84: Non-Graduate | J84: Self-Employed | K84: 2384219 | L84: =IF(K84="","Missing","Submitted") -> Submitted | M84: 454 | N84: =IF(M84<600,"High_risk",IF(M84>=750,"medium_risk","low_risk")) -> High_risk | O84: =IF(J85<503,"Poor",IF(J85<=550,"Fair",IF(J85<=750,"Good","Excellent"))) -> Excellent | P84: =IF(S84="","Missing","Submitted") -> Submitted | Q84: =IF(AND(M84>=300,M84<=900),"Valid","Invalid") -> Valid | R84: Personal | S84: 3231120 | T84: 10.69 | U84: 180 | V84: 17950.67 | W84: =PMT(T84/12,U84,-S84) -> 2878389.4 | X84: Tamil Nadu | Y84: Chennai | Z84: 45546 | AA84: =TEXT(Table2[[#This Row],[Application_Date]],"yyy") -> 2024 | AB84: =TEXT(Table2[[#This Row],[Application_Date]],"mmmm") -> September | AC84: Pending | AD84: No | AE84: West
A85: L100084 | B85: =IF(COUNTIF($A$2:A85,A85)>1,"Duplicate","Unique") -> Unique | C85: C200084 | D85: Sneha Mehta | E85: =IF(C85="","Missing","Submitted") -> Submitted | F85: Male | G85: 32 | H85: Married | I85: Non-Graduate | J85: Government | K85: 347913 | L85: =IF(K85="","Missing","Submitted") -> Submitted | M85: 805 | N85: =IF(M85<600,"High_risk",IF(M85>=750,"medium_risk","low_risk")) -> medium_risk | O85: =IF(J86<503,"Poor",IF(J86<=550,"Fair",IF(J86<=750,"Good","Excellent"))) -> Excellent | P85: =IF(S85="","Missing","Submitted") -> Submitted | Q85: =IF(AND(M85>=300,M85<=900),"Valid","Invalid") -> Valid | R85: Car | S85: 1193879 | T85: 11.69 | U85: 120 | V85: 9948.99 | W85: =PMT(T85/12,U85,-S85) -> 1163037.1 | X85: Karnataka | Y85: Bengaluru | Z85: 45547 | AA85: =TEXT(Table2[[#This Row],[Application_Date]],"yyy") -> 2024 | AB85: =TEXT(Table2[[#This Row],[Application_Date]],"mmmm") -> September | AC85: Approved | AD85: Yes | AE85: North
A86: L100085 | B86: =IF(COUNTIF($A$2:A86,A86)>1,"Duplicate","Unique") -> Unique | C86: C200085 | D86: Amit Sharma | E86: =IF(C86="","Missing","Submitted") -> Submitted | F86: Female | G86: 50 | H86: Single | I86: Graduate | J86: Self-Employed | K86: 718717 | L86: =IF(K86="","Missing","Submitted") -> Submitted | M86: 821 | N86: =IF(M86<600,"High_risk",IF(M86>=750,"medium_risk","low_risk")) -> medium_risk | O86: =IF(J87<503,"Poor",IF(J87<=550,"Fair",IF(J87<=750,"Good","Excellent"))) -> Excellent | P86: =IF(S86="","Missing","Submitted") -> Submitted | Q86: =IF(AND(M86>=300,M86<=900),"Valid","Invalid") -> Valid | R86: Personal | S86: 1111283 | T86: 7.46 | U86: 120 | V86: 9260.69 | W86: =PMT(T86/12,U86,-S86) -> 690847.6 | X86: Karnataka | Y86: Bengaluru | Z86: 45548 | AA86: =TEXT(Table2[[#This Row],[Application_Date]],"yyy") -> 2024 | AB86: =TEXT(Table2[[#This Row],[Application_Date]],"mmmm") -> September | AC86: Approved | AD86: No | AE86: West
A87: L100086 | B87: =IF(COUNTIF($A$2:A87,A87)>1,"Duplicate","Unique") -> Unique | C87: C200086 | D87: Sneha Singh | E87: =IF(C87="","Missing","Submitted") -> Submitted | F87: Female | G87: 37 | H87: Married | I87: Graduate | J87: Self-Employed | K87: 1127775 | L87: =IF(K87="","Missing","Submitted") -> Submitted | M87: 460 | N87: =IF(M87<600,"High_risk",IF(M87>=750,"medium_risk","low_risk")) -> High_risk | O87: =IF(J88<503,"Poor",IF(J88<=550,"Fair",IF(J88<=750,"Good","Excellent"))) -> Excellent | P87: =IF(S87="","Missing","Submitted") -> Submitted | Q87: =IF(AND(M87>=300,M87<=900),"Valid","Invalid") -> Valid | R87: Car | S87: 4346593 | T87: 18.19 | U87: 180 | V87: 24147.74 | W87: =PMT(T87/12,U87,-S87) -> 6588710.6 | X87: Maharashtra | Y87: Mumbai | Z87: 45549 | AA87: =TEXT(Table2[[#This Row],[Application_Date]],"yyy") -> 2024 | AB87: =TEXT(Table2[[#This Row],[Application_Date]],"mmmm") -> September | AC87: Rejected | AD87: No | AE87: West
A88: L100087 | B88: =IF(COUNTIF($A$2:A88,A88)>1,"Duplicate","Unique") -> Unique | C88: C200087 | D88: Amit Sharma | E88: =IF(C88="","Missing","Submitted") -> Submitted | F88: Male | G88: 53 | H88: Single | I88: Non-Graduate | J88: Government | K88: 2488256 | L88: =IF(K88="","Missing","Submitted") -> Submitted | M88: 412 | N88: =IF(M88<600,"High_risk",IF(M88>=750,"medium_risk","low_risk")) -> High_risk | O88: =IF(J89<503,"Poor",IF(J89<=550,"Fair",IF(J89<=750,"Good","Excellent"))) -> Excellent | P88: =IF(S88="","Missing","Submitted") -> Submitted | Q88: =IF(AND(M88>=300,M88<=900),"Valid","Invalid") -> Valid | R88: Personal | S88: 3214653 | T88: 15.68 | U88: 12 | V88: 267887.75 | W88: =PMT(T88/12,U88,-S88) -> 4200665.1 | X88: Rajasthan | Y88: Jaipur | Z88: 45550 | AA88: =TEXT(Table2[[#This Row],[Application_Date]],"yyy") -> 2024 | AB88: =TEXT(Table2[[#This Row],[Application_Date]],"mmmm") -> September | AC88: Pending | AD88: Yes | AE88: South
A89: L100088 | B89: =IF(COUNTIF($A$2:A89,A89)>1,"Duplicate","Unique") -> Unique | C89: C200088 | D89: Rahul Das | E89: =IF(C89="","Missing","Submitted") -> Submitted | F89: Male | G89: 33 | H89: Married | I89: Graduate | J89: Government | K89: 1737389 | L89: =IF(K89="","Missing","Submitted") -> Submitted | M89: 467 | N89: =IF(M89<600,"High_risk",IF(M89>=750,"medium_risk","low_risk")) -> High_risk | O89: =IF(J90<503,"Poor",IF(J90<=550,"Fair",IF(J90<=750,"Good","Excellent"))) -> Excellent | P89: =IF(S89="","Missing","Submitted") -> Submitted | Q89: =IF(AND(M89>=300,M89<=900),"Valid","Invalid") -> Valid | R89: Home | S89: 4175081 | T89: 16.08 | U89: 12 | V89: 347923.42 | W89: =PMT(T89/12,U89,-S89) -> 5594816.1 | X89: UP | Y89: Lucknow | Z89: 45551 | AA89: =TEXT(Table2[[#This Row],[Application_Date]],"yyy") -> 2024 | AB89: =TEXT(Table2[[#This Row],[Application_Date]],"mmmm") -> September | AC89: Approved | AD89: No | AE89: South
A90: L100089 | B90: =IF(COUNTIF($A$2:A90,A90)>1,"Duplicate","Unique") -> Unique | C90: C200089 | D90: Neha Verma | E90: =IF(C90="","Missing","Submitted") -> Submitted | F90: Female | G90: 52 | H90: Married | I90: Graduate | J90: Self-Employed | K90: 1302308 | L90: =IF(K90="","Missing","Submitted") -> Submitted | M90: 772 | N90: =IF(M90<600,"High_risk",IF(M90>=750,"medium_risk","low_risk")) -> medium_risk | O90: =IF(J91<503,"Poor",IF(J91<=550,"Fair",IF(J91<=750,"Good","Excellent"))) -> Excellent | P90: =IF(S90="","Missing","Submitted") -> Submitted | Q90: =IF(AND(M90>=300,M90<=900),"Valid","Invalid") -> Valid | R90: Car | S90: 879878 | T90: 17.1 | U90: 180 | V90: 4888.21 | W90: =PMT(T90/12,U90,-S90) -> 1253826.2 | X90: Rajasthan | Y90: Jaipur | Z90: 45552 | AA90: =TEXT(Table2[[#This Row],[Application_Date]],"yyy") -> 2024 | AB90: =TEXT(Table2[[#This Row],[Application_Date]],"mmmm") -> September | AC90: Approved | AD90: Yes | AE90: West
A91: L100090 | B91: =IF(COUNTIF($A$2:A91,A91)>1,"Duplicate","Unique") -> Unique | C91: C200090 | D91: Rahul Rao | E91: =IF(C91="","Missing","Submitted") -> Submitted | F91: Male | G91: 40 | H91: Single | I91: Graduate | J91: Self-Employed | K91: 2005467 | L91: =IF(K91="","Missing","Submitted") -> Submitted | M91: 406 | N91: =IF(M91<600,"High_risk",IF(M91>=750,"medium_risk","low_risk")) -> High_risk | O91: =IF(J92<503,"Poor",IF(J92<=550,"Fair",IF(J92<=750,"Good","Excellent"))) -> Excellent | P91: =IF(S91="","Missing","Submitted") -> Submitted | Q91: =IF(AND(M91>=300,M91<=900),"Valid","Invalid") -> Valid | R91: Car | S91: 3824443 | T91: 18.38 | U91: 120 | V91: 31870.36 | W91: =PMT(T91/12,U91,-S91) -> 5857771.9 | X91: Maharashtra | Y91: Mumbai | Z91: 45553 | AA91: =TEXT(Table2[[#This Row],[Application_Date]],"yyy") -> 2024 | AB91: =TEXT(Table2[[#This Row],[Application_Date]],"mmmm") -> September | AC91: Approved | AD91: No | AE91: East
A92: L100091 | B92: =IF(COUNTIF($A$2:A92,A92)>1,"Duplicate","Unique") -> Unique | C92: C200091 | D92: Vikas Patel | E92: =IF(C92="","Missing","Submitted") -> Submitted | F92: Female | G92: 35 | H92: Single | I92: Graduate | J92: Business | K92: 494632 | L92: =IF(K92="","Missing","Submitted") -> Submitted | M92: 588 | N92: =IF(M92<600,"High_risk",IF(M92>=750,"medium_risk","low_risk")) -> High_risk | O92: =IF(J93<503,"Poor",IF(J93<=550,"Fair",IF(J93<=750,"Good","Excellent"))) -> Excellent | P92: =IF(S92="","Missing","Submitted") -> Submitted | Q92: =IF(AND(M92>=300,M92<=900),"Valid","Invalid") -> Valid | R92: Business | S92: 2796215 | T92: 10.82 | U92: 60 | V92: 46603.58 | W92: =PMT(T92/12,U92,-S92) -> 2521253.9 | X92: Rajasthan | Y92: Jaipur | Z92: 45554 | AA92: =TEXT(Table2[[#This Row],[Application_Date]],"yyy") -> 2024 | AB92: =TEXT(Table2[[#This Row],[Application_Date]],"mmmm") -> September | AC92: Approved | AD92: Yes | AE92: West
A93: L100092 | B93: =IF(COUNTIF($A$2:A93,A93)>1,"Duplicate","Unique") -> Unique | C93: C200092 | D93: Vikas Sharma | E93: =IF(C93="","Missing","Submitted") -> Submitted | F93: Male | G93: 64 | H93: Married | I93: Non-Graduate | J93: Government | K93: 1131033 | L93: =IF(K93="","Missing","Submitted") -> Submitted | M93: 541 | N93: =IF(M93<600,"High_risk",IF(M93>=750,"medium_risk","low_risk")) -> High_risk | O93: =IF(J94<503,"Poor",IF(J94<=550,"Fair",IF(J94<=750,"Good","Excellent"))) -> Excellent | P93: =IF(S93="","Missing","Submitted") -> Submitted | Q93: =IF(AND(M93>=300,M93<=900),"Valid","Invalid") -> Valid | R93: Business | S93: 2783334 | T93: 17.86 | U93: 12 | V93: 231944.5 | W93: =PMT(T93/12,U93,-S93) -> 4142602.3 | X93: Maharashtra | Y93: Mumbai | Z93: 45555 | AA93: =TEXT(Table2[[#This Row],[Application_Date]],"yyy") -> 2024 | AB93: =TEXT(Table2[[#This Row],[Application_Date]],"mmmm") -> September | AC93: Approved | AD93: Yes | AE93: North
A94: L100093 | B94: =IF(COUNTIF($A$2:A94,A94)>1,"Duplicate","Unique") -> Unique | C94: C200093 | D94: Neha Das | E94: =IF(C94="","Missing","Submitted") -> Submitted | F94: Male | G94: 21 | H94: Married | I94: Non-Graduate | J94: Business | K94: 1983929 | L94: =IF(K94="","Missing","Submitted") -> Submitted | M94: 750 | N94: =IF(M94<600,"High_risk",IF(M94>=750,"medium_risk","low_risk")) -> medium_risk | O94: =IF(J95<503,"Poor",IF(J95<=550,"Fair",IF(J95<=750,"Good","Excellent"))) -> Excellent | P94: =IF(S94="","Missing","Submitted") -> Submitted | Q94: =IF(AND(M94>=300,M94<=900),"Valid","Invalid") -> Valid | R94: Education | S94: 2647438 | T94: 17.3 | U94: 180 | V94: 14707.99 | W94: =PMT(T94/12,U94,-S94) -> 3816723.1 | X94: Karnataka | Y94: Bengaluru | Z94: 45556 | AA94: =TEXT(Table2[[#This Row],[Application_Date]],"yyy") -> 2024 | AB94: =TEXT(Table2[[#This Row],[Application_Date]],"mmmm") -> September | AC94: Pending | AD94: No | AE94: West
...

Sheet pivot table3
A1: Row Labels | B1: Count of Loan_ID | D1: Row Labels | E1: Sum of Credit_Score | G1: Row Labels | H1: Sum of Credit_Score | L1: Credit Score vs Loan Status (Clustered Column)
A2: High_risk | B2: 497 | D2: Rejected | E2: 628537 | G2: Business | H2: 183671 | L2: Default Status Distribution (Pie/Doughnut)
A3: low_risk | B3: 264 | D3: Grand Total | E3: 628537 | G3: Self-Employed | H3: 160763 | L3: Interest Rate by Loan Type (Bar Chart)
A4: medium_risk | B4: 277 | G4: Government | H4: 146233 | L4: Employment Type vs Credit Score (Column Chart)
A5: Grand Total | B5: 1038 | G5: Salaried | H5: 137870 | L5: Branch-wise Average Credit Score
G6: Grand Total | H6: 628537
G8: Row Labels | H8: Average of Credit_Score
A9: Row Labels | B9: Count of Loan_ID | D9: Row Labels | E9: Count of Loan_ID | G9: East | H9: 612.59353
A10: Invalid | B10: 23 | D10: No | E10: 509 | G10: North | H10: 609.57143
A11: Valid | B11: 1015 | D11: Yes | E11: 529 | G11: South | H11: 585.55212
A12: Grand Total | B12: 1038 | D12: Grand Total | E12: 1038 | G12: West | H12: 614.32129
G13: Grand Total | H13: 605.52697
D14: Row Labels | E14: Sum of Interest_Rate
D15: Business | E15: 3910.09
D16: Self-Employed | E16: 3478.68
D17: Government | E17: 3164.89
D18: Salaried | E18: 2919.19
D19: Grand Total | E19: 13472.85

Sheet KPI3
A1: Average of Credit_Score | B1: Total | E1: Count of Valid&invalid credit score | L1: 📊 Average Credit Score
A2: Total | B2: 605.52697 | E2: Valid&invalid credit score | F2: Total | L2: ⚠️ High Risk Customers
B3: =GETPIVOTDATA("Credit_Score",$A$1) -> 605.52697 | E3: Invalid | F3: 23 | L3: ✅ Low Risk Customers
E4: Valid | F4: 1015 | L4: ❌ Invalid Credit Scores
E5: Grand Total | F5: 1038 | L5: 💰 Average Interest Rate
A6: Count of Risk_level | E6: Invalid | F6: =GETPIVOTDATA("Valid&invalid credit score",$E$1,"Valid&invalid credit score","Invalid")/GETPIVOTDATA("Valid&invalid credit score",$E$1) -> 0.022157996 | L6: 🚫 Default Customers
A7: Risk_level | B7: Total
A8: High_risk | B8: 497 | E8: Average of Interest_Rate | F8: Total
A9: low_risk | B9: 264 | E9: Total | F9: 12.979624
A10: medium_risk | B10: 277 | F10: =GETPIVOTDATA("Interest_Rate",$E$8) -> 12.979624
A11: Grand Total | B11: 1038
A12: High_risk | B12: =GETPIVOTDATA("Risk_level",$A$6,"Risk_level","High_Risk")/GETPIVOTDATA("Risk_level",$A$6) -> 0.47880539 | E12: Count of Default_Status
A13: low_risk | B13: =GETPIVOTDATA("Risk_level",$A$6,"Risk_level","low_Risk")/GETPIVOTDATA("Risk_level",$A$6) -> 0.25433526 | E13: Default_Status | F13: Total
E14: No | F14: 509
E15: Yes | F15: 529
E16: Grand Total | F16: 1038 | G16: =GETPIVOTDATA("Default_Status",$E$12) -> 1038
A17: formula:-
A18: GETPIVOTDATA("Valid&invalid credit score",$A$10,"Valid&invalid credit score","valid")/GETPIVOTDATA("Valid&invalid credit score",$A$10)

Sheet Credit Risk & Data Quality

Sheet Bank Loan Analysis Project Summ
G2: Bank Loan Analysis Project Summary
G5: Dashboard | H5: Objective | I5: KPIs | J5: Charts | K5: Slicers | L5: Key Business Insights
G6: Dashboard 1: Loan Performance | H6: Monitor overall loan performance and approval trends. | I6: Total Loan Applications, Total Loan Amount, Approval Rate, Rejection Rate, Average Loan Amount, Average Interest Rate | J6: Loan Status Distribution, Loan Type Distribution, State-wise Loan Amount, Monthly Loan Applications, Branch-wise Loan Amount | K6: State, Branch, Loan Type, Loan Status | L6: Identified top-performing states, most popular loan types, and approval trends across branches.
G7: Dashboard 2: Customer Insights | H7: Analyze customer demographics and borrowing behavior. | I7: Total Customers, Average Age, Average Income, Graduate %, Married %, Average Credit Score | J7: Gender Distribution, Education Distribution, Employment Type, Marital Status, Age Group Distribution, Income Group Distribution | K7: State, Gender, Education, Employment Type | L7: Identified major customer segments, education trends, income distribution, and employment patterns.
G8: Dashboard 3: Credit Risk & Analysis | H8: Evaluate customer credit quality and loan risk. | I8: Average Credit Score, High Risk Customers, Low Risk Customers, Default Customers, Average Interest Rate, Pending Applications | J8: Credit Score Distribution, Credit Score vs Loan Status, Default Status Distribution, Interest Rate by Loan Type, Branch-wise Credit Score, Employment Type vs Credit Score | K8: State, Branch, Employment Type, Loan Status | L8: Identified high-risk customers, default trends, branch performance, and credit score distribution to support better lending decisions.
H13: Data Cleaning Summary
H15: Issue Found | I15: Action Taken
H16: Missing Values | I16: Filled or removed invalid records where appropriate.
H17: Duplicate Records | I17: Removed duplicate Loan_ID entries.
H18: Extra Spaces | I18: Trimmed leading and trailing spaces.
H19: Inconsistent Text | I19: Standardized values such as "Approved", "Rejected", and "Pending".
H20: Invalid Credit Scores | I20: Corrected or removed scores outside the valid range (300–900).
H21: Inconsistent Date Formats | I21: Converted dates to a consistent format.
H22: Data Validation | I22: Verified numeric fields and categorical values for consistency.
H24: Project Overview
H26: Item | I26: Details
H27: Project Name | I27: Bank Loan Analysis Dashboard
H28: Dataset Size | I28: 5,000 Records
H29: Tool Used | I29: Microsoft Excel
H30: Features | I30: Pivot Tables, Pivot Charts, Slicers, KPI Cards, Conditional Formatting
H31: Dashboards | I31: 3 Interactive Dashboards
H32: Data Cleaning | I32: Performed before analysis
H33: Purpose | I33: Analyze loan performance, customer behavior, and credit risk to support business decision-making.
